Workbook
Name ABC: 'Drop DOwn'!$E$2:$E$23
Name ABC: 'Basic Bullets'!$E$1:$E$20
Name aggregatescore: [1]Sheet2!$N$12
Name auditstatus: 'Drop DOwn'!$I$14:$I$15
Name auditstatus: 'Basic Bullets'!$I$12:$I$13
Name BS: '3. Input-BS '!#REF!
Name BS: '3. Input-BS '!#REF!
Name BS: '3. Input-BS '!#REF!
Name BS: '3. Input-BS '!#REF!
Name BS: '3. Input-BS '!#REF!
Name BS: '3. Input-BS '!#REF!
Name BS: '3. Input-BS '!#REF!
Name BS: '3. Input-BS '!#REF!
Name BS: '3. Input-BS '!#REF!
Name BS: '3. Input-BS '!#REF!
Name BS: '3. Input-BS '!#REF!
Name BS: '3. Input-BS '!#REF!
Name BS: '3. Input-BS '!#REF!
Name BS: '3. Input-BS '!#REF!
Name BS: '3. Input-BS '!#REF!
Name BS: '3. Input-BS '!#REF!
Name BS: '3. Input-BS '!#REF!
Name BS: '3. Input-BS '!#REF!
Name BS: '3. Input-BS '!#REF!
Name BS: '3. Input-BS '!#REF!
Name BS: '3. Input-BS '!#REF!
Name BS: '3. Input-BS '!#REF!
Name BS: '3. Input-BS '!#REF!
Name BS: '3. Input-BS '!#REF!
Name BS: '3. Input-BS '!#REF!
Name BS: '3. Input-BS '!#REF!
Name BS: '3. Input-BS '!#REF!
Name BS: '3. Input-BS '!#REF!
Name cement: '7.Cement'!$K$45
Name ceramic: '8. Ceramic'!$H$44
Name chemical: '5. Chemical'!$E$8
Name cibstatus: 'Drop DOwn'!$K$2:$K$6
Name cibstatus: 'Basic Bullets'!$K$1:$K$4
Name fertilizer: '6. Fertilizer'!$N$38
Name food: '3. Food and Allied'!$I$44
Name InBS: '3. Input-BS '!#REF!
Name InBS: '3. Input-BS '!#REF!
Name InBS: '3. Input-BS '!#REF!
Name InBS: '3. Input-BS '!#REF!
Name InBS: '3. Input-BS '!#REF!
Name InBS: '3. Input-BS '!#REF!
Name InBS: '3. Input-BS '!#REF!
Name InBS: '3. Input-BS '!#REF!
Name InBS: '3. Input-BS '!#REF!
Name InBS: '3. Input-BS '!#REF!
Name InBS: '3. Input-BS '!#REF!
Name InBS: '3. Input-BS '!#REF!
Name InBS: '3. Input-BS '!#REF!
Name InBS: '3. Input-BS '!#REF!
Name InBS: '3. Input-BS '!#REF!
Name InBS: '3. Input-BS '!#REF!
Name InBS: '3. Input-BS '!#REF!
Name InBS: '3. Input-BS '!#REF!
Name InBS: '3. Input-BS '!#REF!
Name InBS: '3. Input-BS '!#REF!

Sheet Title
B2: Guidelines on Internal Credit Risk Rating System for Banks
D36: Bangladesh Bank

Sheet Author
B2: Guidelines on Internal Credit Risk Rating System for Banks

Sheet 1. Index
B2: Internal Credit Risk Rating System for Banks
C4: Index
C6: serial | D6: Contents
C7: 1 | D7: Index
C8: 2 | D8: Top Page
C9: 3 | D9: Input Balance Sheet
C10: 4 | D10: Input Profit & Loss Statement
C11: 5 | D11: Input Cashflow Statement
C12: 6 | D12: Output Balance Sheet
C13: 7 | D13: Output Profit and Loss Statement
C14: 8 | D14: Output Cashflow Statement
C15: 9 | D15: Quantitative Analysis
C16: 10 | D16: Qualitative Analysis
C17: 11 | D17: Detail Management Report
C18: 12 | D18: Executive Summary

Sheet 2. Instructions
B3: SL | C3: Particulars
B4: 1 | C4: This is a Microsoft Macro-enabled Excel Input Template and password protected; please do not try to unlock the sheets as such actions may distort data integrety and may make further processing of data/inputs difficult at the end of Bangladesh Bank.
B5: 2 | C5: At this stage, only 3 (three) input sheets have to filled in; Top Page, Input-BS, Input-IS, Input-CF.
B6: 3 | C6: Only Green marked cells are required to be filled, Blue market cells are Dropdown menue from where appropriate option need to be selected.
B7: 4 | C7: Input fields are subject to validation; therefore, appropriate data format have to be used in the in the relevant fields, for example, in the date fields only date data could be entered; in such fields entering other forms of data will result in error message.
B8: 5 | C8: All three input sheets contain comment boxes wherein relevant comments could be made; if the comments do not fit into the allocated space, please use MS word file and mention on which input sheet the comment will apply.
B9: 6 | C9: Filled in Template has to be sent to BRPD, Bangladesh Bank using email addresses: shah.naoaj@bb.org.bd
B10: 7 | C10: All figures will be in thousand.
B11: 8 | C11: Please use extra sheet for making yourself accustomed to populate data ihe template.
B12: 9 | C12: Enter data in the unlocked cells.
B13: 10 | C13: Please don’t use any sign in Input BS/IS. Use negative sign only in CF if necessay.

Sheet Basic Bullets
E1: 1. RMG | F1: 101 | I1: Partnership
E2: 2. Textile | F2: 102 | I2: Private Ltd
E3: 3. Food and Allied | F3: 103 | I3: Public Ltd
E4: 4. Pharmaceuticals | F4: 104
E5: 5. Chemical | F5: 105
E6: 6. Fertilizer | F6: 106 | K6: Standard
E7: 7. Cement | F7: 107 | K7: SMA
E8: 8. Ceramic | F8: 108 | K8: Doubtful
E9: 9. Ship Building | F9: 109 | K9: Substandard
E10: 10. Ship Breaking | F10: 110 | K10: Bad & Loss
E11: 11. Jute Mills | F11: 111 | I11: Audit Status
E12: 12. Steel Engineering | F12: 112 | I12: Audited
E13: 13. Power and Gas | F13: 113 | I13: Unaudited
E14: 14. Other Industries | F14: 114
E15: B. Trade and commerce | F15: 200
E16: C. Agro based and Agro Processing | F16: 300
E17: 1. Housing and Construction | F17: 401
E18: 2. Telecommunication | F18: 402
E19: 3. Hospitals and Clinics | F19: 403
E20: 4. Other Services | F20: 404

Sheet 2. Top Page
B1: Internal Credit Risk Rating System (Top Page)
B4: Internal Credit Risk Scoring System (ICRSS)
B5: Column1 | C5: Column2 | D5: Column3
B6: Bank Name | C6: : | D6: BRAC Bank PLC
B7: Branch Name | C7: : | D7: Corporate & Institutional Banking
B8: File/ Reference No | C8: : | D8: Outpace Spinning Mills Ltd
B9: Borrower Name | C9: : | D9: Outpace Spinning Mills Ltd | G9: A. Industry (please select sub category) | H9: Error: Please Select Sub Group
B10: Group Name, if any | C10: : | D10: Outright Group | G10: 1. RMG | H10: 101
B11: Type of Industry/ Sector | C11: : | D11: 2. Textile | G11: 2. Textile | H11: 102
B12: Industry Code | C12: : | D12: =INDEX('Basic Bullets'!F:F,MATCH('2. Top Page'!D11,'Basic Bullets'!E:E,0)) -> 102 | G12: 3. Food and Allied | H12: 103
B13: Ownership Type | C13: : | D13: Private Ltd Company | G13: 4. Pharmaceuticals | H13: 104
G14: 5. Chemical | H14: 105
B15: CIB Status | C15: : | D15: Standard | G15: 6. Fertilizer | H15: 106
B16: Financial Statement Audit Status: | C16: : | D16: Unaudited | G16: 7. Cement | H16: 107
B17: Name of Audit Farm | C17: : | D17: Dewan Nazrul Islam & Co. | G17: 8. Ceramic | H17: 108
B18: Credit Officer/Analyst Name, Designation | C18: : | D18: Md. Matiur Rahman, SRM | G18: 9. Ship Building | H18: 109
B19: Verifier Name, Designation | C19: : | D19: Farhana Afrin, SM | G19: 10. Ship Breaking | H19: 110
B20: Date of Financials | D20: 45473 | G20: 11. Jute Mills | H20: 111
B21: Date of Analysis (DD-MM-YYYY) | C21: : | D21: 45652 | G21: 12. Steel Engineering | H21: 112
B22: Date of Verification (DD-MM-YYYY) | C22: : | D22: 45736 | G22: 13. Power and Gas | H22: 113
G23: 14. Other Industries | H23: 114
B24: Legend: | G24: B. Trade and commerce | H24: 200
B25: Inputs to be given | G25: C. Agro based and Agro Processing | H25: 300
B26: Select from Drop down list | G26: D. Service (Please select sub category) | H26: Error: Please Select Sub Group
B27: Auto filled cell | G27: 1. Housing and Construction | H27: 401
G28: 2. Telecommunication | H28: 402
B29: Details of Analyst : | G29: 3. Hospitals and Clinics | H29: 403
B30: Name: | C30: Md. Matiur Rahman | G30: 4. Other Services | H30: 404
B31: Designation: | C31: SRM, Large Corporate
B32: Department/Unit/Cell: | C32: Unit- 04
B33: Phone Number:
B34: Email Address:
B35: Alternate Email Address
B36: Details of Verifier:
B37: Name: | C37: Farhana Afrin
B38: Designation: | C38: Senior Manager
B39: Department/Unit/Cell:
B40: Phone Number:
B41: Email Address:
B42: Alternate Email Address
...

Sheet 3. Input-BS 
C4: ='2. Top Page'!D9 -> Outpace Spinning Mills Ltd
C5: Balance Sheet
C6: Analyst | E6: ='2. Top Page'!D18 -> Md. Matiur Rahman, SRM
C7: Verifier | E7: ='2. Top Page'!D19 -> Farhana Afrin, SM
C8: Name of Audit Farm | E8: Deawn Nazrul Islam & Co | F8: Deawn Nazrul Islam & Co | G8: Rahman Mustafiz Haw & Co.
C9: Period (months) | E9: 12 | F9: 12 | G9: 12
C10: Amount in thousand | E10: ('000) | F10: ('000) | G10: ('000)
C11: Statement Year | E11: 2025 | F11: 2024 | G11: 2023
C13: Current Assets: | H13: Commono Size
C14: 1 | D14: Inventories (raw materials+work in progress+Finished Goods) | E14: 2716117.7 | F14: 1547239.4 | G14: 1596103.7 | H14: =E14/$E$51 -> 0.68032647
C15: 2 | D15: Trade Debtors/Accounts Receivables | E15: 350127.01 | F15: 943794.93 | G15: 509309.24 | H15: =E15/$E$51 -> 0.08769895
C16: 3 | D16: Advances, Deposits and Prepayments | E16: 70922.706 | F16: =104353.967-F19-F23 -> 71989.994 | G16: =146578.191-G19-G23 -> 112099.51 | H16: =E16/$E$51 -> 0.017764545
C17: 4 | D17: Cash Subsidy Receivable | E17: 0 | F17: 0 | G17: 0 | H17: =E17/$E$51 -> 0
C18: 5 | D18: Other Receivables | E18: 0 | F18: 0 | G18: 0 | H18: =E18/$E$51 -> 0
C19: 6 | D19: Advance Income Tax | E19: 15902.348 | F19: 9694.682 | G19: 14013.878 | H19: =E19/$E$51 -> 0.003983181
F20: 0 | G20: 0 | H20: =E20/$E$51 -> 0
C21: 7 | D21: Interest Receivables | E21: 0 | F21: 0 | G21: 0 | H21: =E21/$E$51 -> 0
C22: 8 | D22: Loan to Associate/Subsidiary/Inter Company Loan | E22: 0 | F22: 0 | G22: 0 | H22: =E22/$E$51 -> 0
C23: 9 | D23: Short Term Loan/Investment | E23: 17389.659 | F23: 22669.291 | G23: 20464.8 | H23: =E23/$E$51 -> 0.004355719
C24: 10 | D24: Inter Company Receivables/Dues | E24: 0 | F24: 0 | G24: 0 | H24: =E24/$E$51 -> 0
C25: 11 | D25: Investments Held for Sale/Marketable Securities | E25: 0 | F25: 0 | G25: 0 | H25: =E25/$E$51 -> 0
C26: 12 | D26: Goods in Transit | E26: 0 | F26: 0 | G26: 0 | H26: =E26/$E$51 -> 0
C27: 13 | D27: Cash & Bank Balance | E27: 18841.322 | F27: 36951.324 | G27: 17409.703 | H27: =E27/$E$51 -> 0.0047193279
C28: 14 | D28: Other Current Assets | E28: 0 | F28: 0 | G28: 0 | H28: =E28/$E$51 -> 0
C29: 15 | D29: Total Current Assets | E29: =SUM(E14:E28) -> 3189300.7 | F29: =SUM(F14:F28) -> 2632339.6 | G29: =SUM(G14:G28) -> 2269400.9 | H29: =E29/$E$51 -> 0.79884819
C30: 16 | D30: Non-Current Assets: | H30: =E30/$E$51 -> 0
C31: 17 | D31: Net Property, Plant and Equipment | E31: 447186.03 | F31: 416976.52 | G31: 293638.33 | H31: =E31/$E$51 -> 0.11201006
C32: 18 | D32: Net Land and Buildings | E32: 0 | F32: 0 | G32: 0 | H32: =E32/$E$51 -> 0
C33: 19 | D33: Net Furniture & Fixture | E33: 0 | F33: 0 | G33: 0 | H33: =E33/$E$51 -> 0
C34: 20 | D34: Net Other Fixed Assets | E34: 0 | F34: 0 | G34: 0 | H34: =E34/$E$51 -> 0
C35: 21 | D35: Goodwill | E35: 0 | F35: 0 | G35: 0 | H35: =E35/$E$51 -> 0
C36: 22 | D36: Trademark/Patent/Software | E36: 0 | F36: 0 | G36: 0 | H36: =E36/$E$51 -> 0
C37: 23 | D37: other Intangible Assets | E37: 0 | F37: 0 | G37: 0 | H37: =E37/$E$51 -> 0
C38: 24 | D38: Investment in Subsidiary and Associates/ Joint Venture | E38: 300000 | F38: 300000 | G38: 300000 | H38: =E38/$E$51 -> 0.075143261
C39: 25 | D39: Investment in Shares/Bond | E39: 0 | F39: 0 | G39: 0 | H39: =E39/$E$51 -> 0
C40: 26 | D40: Other Investments | E40: 0 | F40: 0 | G40: 0 | H40: =E40/$E$51 -> 0
C41: 27 | D41: Deferred Tax Assets | E41: 0 | F41: 0 | G41: 0 | H41: =E41/$E$51 -> 0
C42: 28 | D42: Loan to Subsidiary/Associate | E42: 0 | F42: 0 | G42: 0 | H42: =E42/$E$51 -> 0
... C48: 34 | D48: Other Long Term Receivables | E48: 0 | F48: 0 | G48: 0 | H48: =E48/$E$51 -> 0
C49: 35 | D49: Other Non-Current Assets | E49: 55887.219 | F49: 50013.1 | G49: =327375.554-G38 -> 27375.554 | H49: =E49/$E$51 -> 0.013998493
...

Sheet 4. Input P&L
C2: ='2. Top Page'!D9 -> Outpace Spinning Mills Ltd
C3: Profit & Loss Statement
C4: Analyst | E4: ='2. Top Page'!D18 -> Md. Matiur Rahman, SRM
C5: Verifier | E5: ='2. Top Page'!D19 -> Farhana Afrin, SM
C6: Name of Audit Farm | E6: ='3. Input-BS '!E8 -> Deawn Nazrul Islam & Co | F6: ='3. Input-BS '!F8 -> Deawn Nazrul Islam & Co | G6: ='3. Input-BS '!G8 -> Rahman Mustafiz Haw & Co.
C7: Period (months) | E7: ='3. Input-BS '!E9 -> 12 | F7: ='3. Input-BS '!F9 -> 12 | G7: ='3. Input-BS '!G9 -> 12
C8: Amount in thousand | E8: ('000) | F8: ('000) | G8: ('000)
C9: Statement Year | E9: ='3. Input-BS '!E11 -> 2025 | F9: ='3. Input-BS '!F11 -> 2024 | G9: ='3. Input-BS '!G11 -> 2023
H10: Common Size
C11: 1 | D11: Sales /Revenue/Turnover | E11: 1412760.6 | F11: 1736066.4 | G11: 1396131.3 | H11: =E11/$E$11 -> 1
C12: 2 | D12: VAT & Supplementary Duty | E12: 0 | F12: 0 | G12: 0 | H12: =E12/$E$11 -> 0
C13: 3 | D13: Net Sales/Revenue | E13: =E11-E12 -> 1412760.6 | F13: =IFERROR(F11-F12,"recheck") -> 1736066.4 | G13: =IFERROR(G11-G12,"recheck") -> 1396131.3 | H13: =E13/$E$11 -> 1
C14: 4 | D14: Cost of Goods/Service Sold | E14: =1207915.521-E19 -> 1187045.5 | F14: =1493014.199-F19 -> 1473623.9 | G14: =1157634.474-G19 -> 1144305.5 | H14: =E14/$E$11 -> 0.84023119
C15: 5 | D15: Gross Profit | E15: =E13-E14 -> 225715.08 | F15: =F13-F14 -> 262442.55 | G15: =G13-G14 -> 251825.83 | H15: =E15/$E$11 -> 0.15976881
C16: 6 | D16: Salaries | E16: 0 | F16: 0 | G16: 0 | H16: =E16/$E$11 -> 0
C17: 7 | D17: Marketing, Selling & Distribution Expenses | E17: 3381.175 | F17: 4765.77 | G17: 34597.824 | H17: =E17/$E$11 -> 0.0023933107
C18: 8 | D18: Administrative Expenses | E18: 29692.632 | F18: 41358.161 | G18: 4194.973 | H18: =E18/$E$11 -> 0.021017455
C19: 9 | D19: Depreciation/ Amortization | E19: 20870.038 | F19: 19390.317 | G19: 13328.984 | H19: =E19/$E$11 -> 0.014772523
C20: 10 | D20: Other Operating Expense | E20: 0 | F20: 0 | G20: 0 | H20: =E20/$E$11 -> 0
C21: 11 | D21: Total Operating Expenses | E21: =SUM(E16:E20) -> 53943.845 | F21: =SUM(F16:F20) -> 65514.248 | G21: =SUM(G16:G20) -> 52121.781 | H21: =E21/$E$11 -> 0.038183289
C22: 12 | D22: Other Operating Income | E22: 0 | F22: 0 | G22: 0 | H22: =E22/$E$11 -> 0
C23: 13 | D23: Operating Profit | E23: =E15+E22-E21 -> 171771.23 | F23: =F15-F21+F22 -> 196928.31 | G23: =G15-G21+G22 -> 199704.05 | H23: =E23/$E$11 -> 0.12158552
C24: 14 | D24: Exchange Gain | E24: 0 | F24: 0 | G24: 0 | H24: =E24/$E$11 -> 0
C25: 15 | D25: Exchang Loss | E25: 0 | F25: 0 | G25: 0 | H25: =E25/$E$11 -> 0
C26: 16 | D26: Investment/Interest Income | E26: 0 | F26: 0 | G26: 0 | H26: =E26/$E$11 -> 0
C27: 17 | D27: Rental Income | E27: 0 | F27: 0 | G27: 0 | H27: =E27/$E$11 -> 0
C28: 18 | D28: Gain on Disposals of Fixed Assets | E28: 0 | F28: 0 | G28: 0 | H28: =E28/$E$11 -> 0
C29: 19 | D29: Loss on Disposals of Fixed Assets | E29: 0 | F29: 0 | G29: 0 | H29: =E29/$E$11 -> 0
C30: 20 | D30: Surplus on Revaluation of Property | E30: 0 | F30: 0 | G30: 0 | H30: =E30/$E$11 -> 0
C31: 21 | D31: Deficit on Revaluation of Property | E31: 0 | F31: 0 | G31: 0 | H31: =E31/$E$11 -> 0
C32: 22 | D32: Other Income | E32: 1975.013 | F32: 2785.613 | G32: 738.384 | H32: =E32/$E$11 -> 0.0013979814
C33: 23 | D33: Other Expenses | E33: 0 | F33: 0 | G33: 0 | H33: =E33/$E$11 -> 0
C34: 24 | D34: Provision For Welfare and profit participation fund | E34: 0 | F34: 0 | G34: 0 | H34: =E34/$E$11 -> 0
C35: 25 | D35: Share of profit from associates | E35: 0 | F35: 0 | G35: 0 | H35: =E35/$E$11 -> 0
C36: 26 | D36: Share of loss from associates | E36: 0 | F36: 0 | G36: 0 | H36: =E36/$E$11 -> 0
C37: 27 | D37: Earnings Before Interest and Tax (EBIT) | E37: =E23+E24-E25+E26+E27+E28-E29+E30-E31+E32-E33-E34+E35-E36 -> 173746.24 | F37: =F23+F24-F25+F26+F27+F28-F29+F30-F31+F32-F33-F34+F35-F36 -> 199713.92 | G37: =G23+G24-G25+G26+G27+G28-G29+G30-G31+G32-G33-G34+G35-G36 -> 200442.43 | H37: =E37/$E$11 -> 0.1229835
C38: 28 | D38: Financial/Interest Expenses | E38: 80287.596 | F38: 118784.16 | G38: 68706.248 | H38: =E38/$E$11 -> 0.056830293
C39: 29 | D39: Earnings Before Tax (EBT) | E39: =IF(E38=0,"please_insert_value_in_row_38: Financial/Interest Expenses",E37-E38) -> 93458.648 | F39: =IF(F38=0,"please_insert_value_in_row_38: Financial/Interest Expenses",F37-F38) -> 80929.762 | G39: =IF(G38=0,"please_insert_value_in_row_38: Financial/Interest Expenses",G37-G38) -> 131736.19 | H39: =E39/$E$11 -> 0.066153211
C40: 30 | D40: Current Tax | E40: 15902.348 | F40: 11393.965 | G40: 19760.428 | H40: =E40/$E$11 -> 0.011256223
C41: 31 | D41: Deferred Tax/ Advance Tax Expense | E41: 0 | F41: 0 | H41: =E41/$E$11 -> 0
...

Sheet 5. Input-CF
C2: ='2. Top Page'!D9 -> Outpace Spinning Mills Ltd
C3: Cash Flow Statement
C4: Analyst | E4: ='2. Top Page'!D18 -> Md. Matiur Rahman, SRM
C5: Verifier | E5: ='2. Top Page'!D19 -> Farhana Afrin, SM
C6: Name of the Audit Farm | E6: ='3. Input-BS '!E8 -> Deawn Nazrul Islam & Co | F6: ='3. Input-BS '!F8 -> Deawn Nazrul Islam & Co | G6: ='3. Input-BS '!G8 -> Rahman Mustafiz Haw & Co.
C7: Period (months) | E7: ='3. Input-BS '!E9 -> 12 | F7: ='3. Input-BS '!F9 -> 12 | G7: ='3. Input-BS '!G9 -> 12
C8: Amount in thousand | E8: ('000) | F8: ('000) | G8: ('000)
C10: Year | E10: ='3. Input-BS '!E11 -> 2025 | F10: ='3. Input-BS '!F11 -> 2024 | G10: ='3. Input-BS '!G11 -> 2023
C11: A. | D11: Net cash flows from operating activities | E11: 105171.03 | F11: 398401.77 | G11: -723188.92
C12: B. | D12: Net cash flows from investing activities | E12: -56953.665 | F12: -165366.05 | G12: -20827.202
C13: C. | D13: Net cash flows from financing activities | E13: -66327.363 | F13: -213494.1 | G13: 748507.59
C14: D. | D14: Net inflow of cash and cash equivalents | E14: =SUM(E11:E13) -> -18110.002 | F14: =SUM(F11:F13) -> 19541.621 | G14: =SUM(G11:G13) -> 4491.471
C15: E. | D15: Cash and cash equivalent at opening | E15: 36951.324 | F15: 17409.703 | G15: 12918.232
C16: F | D16: Cash and cash equivalent at closing | E16: =E14+E15 -> 18841.322 | F16: =F14+F15 -> 36951.324 | G16: =G14+G15 -> 17409.703
C18: Note: Please use sign (+/-) with the figures if needed.
D19: Example: if cash flow from operation is negative 100 provide input -100.

Sheet 6. Output-BS
C2: ='2. Top Page'!D9 -> Outpace Spinning Mills Ltd
C3: ='3. Input-BS '!C5:G5 -> Balance Sheet
C4: ='3. Input-BS '!C6:D6 -> Analyst | E4: ='2. Top Page'!D18 -> Md. Matiur Rahman, SRM
C5: Verifier | E5: ='2. Top Page'!D19 -> Farhana Afrin, SM
C6: ='3. Input-BS '!C8:D8 -> Name of Audit Farm | E6: ='3. Input-BS '!E8 -> Deawn Nazrul Islam & Co | F6: ='3. Input-BS '!F8 -> Deawn Nazrul Islam & Co | G6: ='3. Input-BS '!G8 -> Rahman Mustafiz Haw & Co.
C7: ='3. Input-BS '!C9:D9 -> Period (months) | E7: ='3. Input-BS '!E9 -> 12 | F7: ='3. Input-BS '!F9 -> 12 | G7: ='3. Input-BS '!G9 -> 12
C8: ='3. Input-BS '!C10:D10 -> Amount in thousand | E8: ='3. Input-BS '!E10 -> ('000) | F8: ='3. Input-BS '!F10 -> ('000) | G8: ='3. Input-BS '!G10 -> ('000)
C9: ='3. Input-BS '!C11:D11 -> Statement Year | E9: ='3. Input-BS '!E11 -> 2025 | F9: ='3. Input-BS '!F11 -> 2024 | G9: ='3. Input-BS '!G11 -> 2023
C11: ='3. Input-BS '!C13:D13 -> Current Assets:
C12: ='3. Input-BS '!C14 -> 1 | D12: ='3. Input-BS '!D14 -> Inventories (raw materials+work in progress+Finished Goods) | E12: ='3. Input-BS '!E14 -> 2716117.7 | F12: ='3. Input-BS '!F14 -> 1547239.4 | G12: ='3. Input-BS '!G14 -> 1596103.7
C13: ='3. Input-BS '!C15 -> 2 | D13: ='3. Input-BS '!D15 -> Trade Debtors/Accounts Receivables | E13: ='3. Input-BS '!E15 -> 350127.01 | F13: ='3. Input-BS '!F15 -> 943794.93 | G13: ='3. Input-BS '!G15 -> 509309.24
C14: ='3. Input-BS '!C16 -> 3 | D14: ='3. Input-BS '!D16 -> Advances, Deposits and Prepayments | E14: ='3. Input-BS '!E16 -> 70922.706 | F14: ='3. Input-BS '!F16 -> 71989.994 | G14: ='3. Input-BS '!G16 -> 112099.51
C15: ='3. Input-BS '!C17 -> 4 | D15: ='3. Input-BS '!D17 -> Cash Subsidy Receivable | E15: ='3. Input-BS '!E17 -> 0 | F15: ='3. Input-BS '!F17 -> 0 | G15: ='3. Input-BS '!G17 -> 0
C16: ='3. Input-BS '!C18 -> 5 | D16: ='3. Input-BS '!D18 -> Other Receivables | E16: ='3. Input-BS '!E18 -> 0 | F16: ='3. Input-BS '!F18 -> 0 | G16: ='3. Input-BS '!G18 -> 0
C17: ='3. Input-BS '!C19 -> 6 | D17: ='3. Input-BS '!D19 -> Advance Income Tax | E17: ='3. Input-BS '!E19 -> 15902.348 | F17: ='3. Input-BS '!F19 -> 9694.682 | G17: ='3. Input-BS '!G19 -> 14013.878
C18: ='3. Input-BS '!C20 -> 0 | D18: ='3. Input-BS '!D20 -> 0 | E18: ='3. Input-BS '!E20 -> 0 | F18: ='3. Input-BS '!F20 -> 0 | G18: ='3. Input-BS '!G20 -> 0
C19: ='3. Input-BS '!C21 -> 7 | D19: ='3. Input-BS '!D21 -> Interest Receivables | E19: ='3. Input-BS '!E21 -> 0 | F19: ='3. Input-BS '!F21 -> 0 | G19: ='3. Input-BS '!G21 -> 0
C20: ='3. Input-BS '!C22 -> 8 | D20: ='3. Input-BS '!D22 -> Loan to Associate/Subsidiary/Inter Company Loan | E20: ='3. Input-BS '!E22 -> 0 | F20: ='3. Input-BS '!F22 -> 0 | G20: ='3. Input-BS '!G22 -> 0
C21: ='3. Input-BS '!C23 -> 9 | D21: ='3. Input-BS '!D23 -> Short Term Loan/Investment | E21: ='3. Input-BS '!E23 -> 17389.659 | F21: ='3. Input-BS '!F23 -> 22669.291 | G21: ='3. Input-BS '!G23 -> 20464.8
C22: ='3. Input-BS '!C24 -> 10 | D22: ='3. Input-BS '!D24 -> Inter Company Receivables/Dues | E22: ='3. Input-BS '!E24 -> 0 | F22: ='3. Input-BS '!F24 -> 0 | G22: ='3. Input-BS '!G24 -> 0
C23: ='3. Input-BS '!C25 -> 11 | D23: ='3. Input-BS '!D25 -> Investments Held for Sale/Marketable Securities | E23: ='3. Input-BS '!E25 -> 0 | F23: ='3. Input-BS '!F25 -> 0 | G23: ='3. Input-BS '!G25 -> 0
... C26: ='3. Input-BS '!C28 -> 14 | D26: ='3. Input-BS '!D28 -> Other Current Assets | E26: ='3. Input-BS '!E28 -> 0 | F26: ='3. Input-BS '!F28 -> 0 | G26: ='3. Input-BS '!G28 -> 0
D27: ='3. Input-BS '!D29 -> Total Current Assets | E27: ='3. Input-BS '!E29 -> 3189300.7 | F27: ='3. Input-BS '!F29 -> 2632339.6 | G27: ='3. Input-BS '!G29 -> 2269400.9
D28: ='3. Input-BS '!D30 -> Non-Current Assets: | E28: ='3. Input-BS '!E30 -> 0 | F28: ='3. Input-BS '!F30 -> 0 | G28: ='3. Input-BS '!G30 -> 0
C29: ='3. Input-BS '!C31 -> 17 | D29: ='3. Input-BS '!D31 -> Net Property, Plant and Equipment | E29: ='3. Input-BS '!E31 -> 447186.03 | F29: ='3. Input-BS '!F31 -> 416976.52 | G29: ='3. Input-BS '!G31 -> 293638.33
C30: ='3. Input-BS '!C32 -> 18 | D30: ='3. Input-BS '!D32 -> Net Land and Buildings | E30: ='3. Input-BS '!E32 -> 0 | F30: ='3. Input-BS '!F32 -> 0 | G30: ='3. Input-BS '!G32 -> 0
C31: ='3. Input-BS '!C33 -> 19 | D31: ='3. Input-BS '!D33 -> Net Furniture & Fixture | E31: ='3. Input-BS '!E33 -> 0 | F31: ='3. Input-BS '!F33 -> 0 | G31: ='3. Input-BS '!G33 -> 0
C32: ='3. Input-BS '!C30 -> 16 | D32: ='3. Input-BS '!D34 -> Net Other Fixed Assets | E32: ='3. Input-BS '!E34 -> 0 | F32: ='3. Input-BS '!F34 -> 0 | G32: ='3. Input-BS '!G34 -> 0
C33: ='3. Input-BS '!C35 -> 21 | D33: ='3. Input-BS '!D35 -> Goodwill | E33: ='3. Input-BS '!E35 -> 0 | F33: ='3. Input-BS '!F35 -> 0 | G33: ='3. Input-BS '!G35 -> 0
C34: ='3. Input-BS '!C36 -> 22 | D34: ='3. Input-BS '!D36 -> Trademark/Patent/Software | E34: ='3. Input-BS '!E36 -> 0 | F34: ='3. Input-BS '!F36 -> 0 | G34: ='3. Input-BS '!G36 -> 0
C35: ='3. Input-BS '!C37 -> 23 | D35: ='3. Input-BS '!D37 -> other Intangible Assets | E35: ='3. Input-BS '!E37 -> 0 | F35: ='3. Input-BS '!F37 -> 0 | G35: ='3. Input-BS '!G37 -> 0
C36: ='3. Input-BS '!C38 -> 24 | D36: ='3. Input-BS '!D38 -> Investment in Subsidiary and Associates/ Joint Venture | E36: ='3. Input-BS '!E38 -> 300000 | F36: ='3. Input-BS '!F38 -> 300000 | G36: ='3. Input-BS '!G38 -> 300000
C37: ='3. Input-BS '!C39 -> 25 | D37: ='3. Input-BS '!D39 -> Investment in Shares/Bond | E37: ='3. Input-BS '!E39 -> 0 | F37: ='3. Input-BS '!F39 -> 0 | G37: ='3. Input-BS '!G39 -> 0
C38: ='3. Input-BS '!C40 -> 26 | D38: ='3. Input-BS '!D40 -> Other Investments | E38: ='3. Input-BS '!E40 -> 0 | F38: ='3. Input-BS '!F40 -> 0 | G38: ='3. Input-BS '!G40 -> 0
C39: ='3. Input-BS '!C41 -> 27 | D39: ='3. Input-BS '!D41 -> Deferred Tax Assets | E39: ='3. Input-BS '!E41 -> 0 | F39: ='3. Input-BS '!F41 -> 0 | G39: ='3. Input-BS '!G41 -> 0
C40: ='3. Input-BS '!C42 -> 28 | D40: ='3. Input-BS '!D42 -> Loan to Subsidiary/Associate | E40: ='3. Input-BS '!E42 -> 0 | F40: ='3. Input-BS '!F42 -> 0 | G40: ='3. Input-BS '!G42 -> 0
C41: ='3. Input-BS '!C43 -> 29 | D41: ='3. Input-BS '!D43 -> Preliminary Expenses | E41: ='3. Input-BS '!E43 -> 0 | F41: ='3. Input-BS '!F43 -> 0 | G41: ='3. Input-BS '!G43 -> 0
C42: ='3. Input-BS '!C44 -> 30 | D42: ='3. Input-BS '!D44 -> Product Development Cost | E42: ='3. Input-BS '!E44 -> 0 | F42: ='3. Input-BS '!F44 -> 0 | G42: ='3. Input-BS '!G44 -> 0
C43: ='3. Input-BS '!C45 -> 31 | D43: ='3. Input-BS '!D45 -> Capital Work In Progress | E43: ='3. Input-BS '!E45 -> 0 | F43: ='3. Input-BS '!F45 -> 0 | G43: ='3. Input-BS '!G45 -> 0
C44: ='3. Input-BS '!C46 -> 32 | D44: ='3. Input-BS '!D46 -> Prepayment of Rent | E44: ='3. Input-BS '!E46 -> 0 | F44: ='3. Input-BS '!F46 -> 0 | G44: ='3. Input-BS '!G46 -> 0
...

Sheet 7. Output IS
C2: ='4. Input P&L'!C2:G2 -> Outpace Spinning Mills Ltd
C3: ='4. Input P&L'!C3:G3 -> Profit & Loss Statement
C4: ='4. Input P&L'!C4:D4 -> Analyst | E4: ='4. Input P&L'!E4:G4 -> Md. Matiur Rahman, SRM
C5: ='4. Input P&L'!C5:D5 -> Verifier | E5: ='4. Input P&L'!E5:G5 -> Farhana Afrin, SM
C6: ='4. Input P&L'!C6:D6 -> Name of Audit Farm | E6: ='4. Input P&L'!E6 -> Deawn Nazrul Islam & Co | F6: ='4. Input P&L'!F6 -> Deawn Nazrul Islam & Co | G6: ='4. Input P&L'!G6 -> Rahman Mustafiz Haw & Co.
C7: ='4. Input P&L'!C7:D7 -> Period (months) | E7: ='4. Input P&L'!E7 -> 12 | F7: ='4. Input P&L'!F7 -> 12 | G7: ='4. Input P&L'!G7 -> 12
C8: ='4. Input P&L'!C8:D8 -> Amount in thousand | E8: ('000) | F8: ('000) | G8: ('000)
C9: ='4. Input P&L'!C9:D9 -> Statement Year | E9: ='4. Input P&L'!E9 -> 2025 | F9: ='4. Input P&L'!F9 -> 2024 | G9: ='4. Input P&L'!G9 -> 2023
C11: ='4. Input P&L'!C11 -> 1 | D11: ='4. Input P&L'!D11 -> Sales /Revenue/Turnover | E11: ='4. Input P&L'!E11 -> 1412760.6 | F11: ='4. Input P&L'!F11 -> 1736066.4 | G11: ='4. Input P&L'!G11 -> 1396131.3
C12: ='4. Input P&L'!C12 -> 2 | D12: ='4. Input P&L'!D12 -> VAT & Supplementary Duty | E12: ='4. Input P&L'!E12 -> 0 | F12: ='4. Input P&L'!F12 -> 0 | G12: ='4. Input P&L'!G12 -> 0
C13: ='4. Input P&L'!C13 -> 3 | D13: ='4. Input P&L'!D13 -> Net Sales/Revenue | E13: ='4. Input P&L'!E13 -> 1412760.6 | F13: ='4. Input P&L'!F13 -> 1736066.4 | G13: ='4. Input P&L'!G13 -> 1396131.3
C14: ='4. Input P&L'!C14 -> 4 | D14: ='4. Input P&L'!D14 -> Cost of Goods/Service Sold | E14: ='4. Input P&L'!E14 -> 1187045.5 | F14: ='4. Input P&L'!F14 -> 1473623.9 | G14: ='4. Input P&L'!G14 -> 1144305.5
C15: ='4. Input P&L'!C15 -> 5 | D15: ='4. Input P&L'!D15 -> Gross Profit | E15: ='4. Input P&L'!E15 -> 225715.08 | F15: ='4. Input P&L'!F15 -> 262442.55 | G15: ='4. Input P&L'!G15 -> 251825.83
C16: ='4. Input P&L'!C16 -> 6 | D16: ='4. Input P&L'!D16 -> Salaries | E16: ='4. Input P&L'!E16 -> 0 | F16: ='4. Input P&L'!F16 -> 0 | G16: ='4. Input P&L'!G16 -> 0
C17: ='4. Input P&L'!C17 -> 7 | D17: ='4. Input P&L'!D17 -> Marketing, Selling & Distribution Expenses | E17: ='4. Input P&L'!E17 -> 3381.175 | F17: ='4. Input P&L'!F17 -> 4765.77 | G17: ='4. Input P&L'!G17 -> 34597.824
C18: ='4. Input P&L'!C18 -> 8 | D18: ='4. Input P&L'!D18 -> Administrative Expenses | E18: ='4. Input P&L'!E18 -> 29692.632 | F18: ='4. Input P&L'!F18 -> 41358.161 | G18: ='4. Input P&L'!G18 -> 4194.973
C19: ='4. Input P&L'!C19 -> 9 | D19: ='4. Input P&L'!D19 -> Depreciation/ Amortization | E19: ='4. Input P&L'!E19 -> 20870.038 | F19: ='4. Input P&L'!F19 -> 19390.317 | G19: ='4. Input P&L'!G19 -> 13328.984
C20: ='4. Input P&L'!C20 -> 10 | D20: ='4. Input P&L'!D20 -> Other Operating Expense | E20: ='4. Input P&L'!E20 -> 0 | F20: ='4. Input P&L'!F20 -> 0 | G20: ='4. Input P&L'!G20 -> 0
C21: ='4. Input P&L'!C21 -> 11 | D21: ='4. Input P&L'!D21 -> Total Operating Expenses | E21: ='4. Input P&L'!E21 -> 53943.845 | F21: ='4. Input P&L'!F21 -> 65514.248 | G21: ='4. Input P&L'!G21 -> 52121.781
C22: ='4. Input P&L'!C22 -> 12 | D22: ='4. Input P&L'!D22 -> Other Operating Income | E22: ='4. Input P&L'!E22 -> 0 | F22: ='4. Input P&L'!F22 -> 0 | G22: ='4. Input P&L'!G22 -> 0
... C35: ='4. Input P&L'!C35 -> 25 | D35: ='4. Input P&L'!D35 -> Share of profit from associates | E35: ='4. Input P&L'!E35 -> 0 | F35: ='4. Input P&L'!F35 -> 0 | G35: ='4. Input P&L'!G35 -> 0
C36: ='4. Input P&L'!C37 -> 27 | D36: ='4. Input P&L'!D37 -> Earnings Before Interest and Tax (EBIT) | E36: ='4. Input P&L'!E37 -> 173746.24 | F36: ='4. Input P&L'!F37 -> 199713.92 | G36: ='4. Input P&L'!G37 -> 200442.43
C37: ='4. Input P&L'!C38 -> 28 | D37: ='4. Input P&L'!D38 -> Financial/Interest Expenses | E37: ='4. Input P&L'!E38 -> 80287.596 | F37: ='4. Input P&L'!F38 -> 118784.16 | G37: ='4. Input P&L'!G38 -> 68706.248
C38: ='4. Input P&L'!C39 -> 29 | D38: ='4. Input P&L'!D39 -> Earnings Before Tax (EBT) | E38: ='4. Input P&L'!E39 -> 93458.648 | F38: ='4. Input P&L'!F39 -> 80929.762 | G38: ='4. Input P&L'!G39 -> 131736.19
C39: ='4. Input P&L'!C40 -> 30 | D39: ='4. Input P&L'!D40 -> Current Tax | E39: ='4. Input P&L'!E40 -> 15902.348 | F39: ='4. Input P&L'!F40 -> 11393.965 | G39: ='4. Input P&L'!G40 -> 19760.428
C40: ='4. Input P&L'!C41 -> 31 | D40: ='4. Input P&L'!D41 -> Deferred Tax/ Advance Tax Expense | E40: ='4. Input P&L'!E41 -> 0 | F40: ='4. Input P&L'!F41 -> 0 | G40: ='4. Input P&L'!G41 -> 0
C41: ='4. Input P&L'!C42 -> 32 | D41: ='4. Input P&L'!D42 -> Deferred Tax/Advance Tax Income | E41: ='4. Input P&L'!E42 -> 0 | F41: ='4. Input P&L'!F42 -> 0 | G41: ='4. Input P&L'!G42 -> 0
C42: ='4. Input P&L'!C43 -> 33 | D42: ='4. Input P&L'!D43 -> Total Tax | E42: ='4. Input P&L'!E43 -> 15902.348 | F42: ='4. Input P&L'!F43 -> 11393.965 | G42: ='4. Input P&L'!G43 -> 19760.428
C43: ='4. Input P&L'!C44 -> 34 | D43: ='4. Input P&L'!D44 -> Net Profit After Tax (NPAT) | E43: ='4. Input P&L'!E44 -> 77556.3 | F43: ='4. Input P&L'!F44 -> 69535.797 | G43: ='4. Input P&L'!G44 -> 111975.76
C44: ='4. Input P&L'!C45 -> 35 | D44: ='4. Input P&L'!D45 -> Extraordinary Income/ Other Comprehensive Income | E44: ='4. Input P&L'!E45 -> 0 | F44: ='4. Input P&L'!F45 -> 0 | G44: ='4. Input P&L'!G45 -> 0
C45: ='4. Input P&L'!C46 -> 36 | D45: ='4. Input P&L'!D46 -> Extraordinary Expenses/ Other Comprehensive Expense | E45: ='4. Input P&L'!E46 -> 0 | F45: ='4. Input P&L'!F46 -> 0 | G45: ='4. Input P&L'!G46 -> 0
C46: ='4. Input P&L'!C47 -> 37 | D46: ='4. Input P&L'!D47 -> Total Comprehensive Income | E46: ='4. Input P&L'!E47 -> 77556.3 | F46: ='4. Input P&L'!F47 -> 69535.797 | G46: ='4. Input P&L'!G47 -> 111975.76

Sheet 8. Output CF
C2: ='2. Top Page'!D9 -> Outpace Spinning Mills Ltd
C3: Cash Flow Statement
C4: ='5. Input-CF'!C4:D4 -> Analyst | E4: ='2. Top Page'!D18 -> Md. Matiur Rahman, SRM
C5: ='5. Input-CF'!C5:D5 -> Verifier | E5: ='2. Top Page'!D19 -> Farhana Afrin, SM
C6: ='5. Input-CF'!C6:D6 -> Name of the Audit Farm | E6: ='5. Input-CF'!E6 -> Deawn Nazrul Islam & Co | F6: ='5. Input-CF'!F6 -> Deawn Nazrul Islam & Co | G6: ='5. Input-CF'!G6 -> Rahman Mustafiz Haw & Co.
C7: ='5. Input-CF'!C7:D7 -> Period (months) | E7: ='4. Input P&L'!E7 -> 12 | F7: ='4. Input P&L'!F7 -> 12 | G7: ='4. Input P&L'!G7 -> 12
C8: ='5. Input-CF'!C8:D8 -> Amount in thousand | E8: ('000) | F8: ('000) | G8: ('000)
C10: Year | E10: ='5. Input-CF'!E10 -> 2025 | F10: ='5. Input-CF'!F10 -> 2024 | G10: ='5. Input-CF'!G10 -> 2023
C11: ='5. Input-CF'!C11 -> A. | D11: ='5. Input-CF'!D11 -> Net cash flows from operating activities | E11: ='5. Input-CF'!E11 -> 105171.03 | F11: ='5. Input-CF'!F11 -> 398401.77 | G11: ='5. Input-CF'!G11 -> -723188.92
C12: ='5. Input-CF'!C12 -> B. | D12: ='5. Input-CF'!D12 -> Net cash flows from investing activities | E12: ='5. Input-CF'!E12 -> -56953.665 | F12: ='5. Input-CF'!F12 -> -165366.05 | G12: ='5. Input-CF'!G12 -> -20827.202
C13: ='5. Input-CF'!C13 -> C. | D13: ='5. Input-CF'!D13 -> Net cash flows from financing activities | E13: ='5. Input-CF'!E13 -> -66327.363 | F13: ='5. Input-CF'!F13 -> -213494.1 | G13: ='5. Input-CF'!G13 -> 748507.59
C14: ='5. Input-CF'!C14 -> D. | D14: ='5. Input-CF'!D14 -> Net inflow of cash and cash equivalents | E14: ='5. Input-CF'!E14 -> -18110.002 | F14: ='5. Input-CF'!F14 -> 19541.621 | G14: ='5. Input-CF'!G14 -> 4491.471
C15: ='5. Input-CF'!C15 -> E. | D15: ='5. Input-CF'!D15 -> Cash and cash equivalent at opening | E15: ='5. Input-CF'!E15 -> 36951.324 | F15: ='5. Input-CF'!F15 -> 17409.703 | G15: ='5. Input-CF'!G15 -> 12918.232
C16: E. | D16: Cash and cash equivalent at closing | E16: =SUM(E14:E15) -> 18841.322 | F16: =SUM(F14:F15) -> 36951.324 | G16: =SUM(G14:G15) -> 17409.703

Sheet Final Graph
B2: Components for Analysis
D3: ='6. Output-BS'!E9 -> 2025 | E3: ='6. Output-BS'!F9 -> 2024 | F3: ='6. Output-BS'!G9 -> 2023 | G3: =E3 -> 2024 | H3: =D3 -> 2025
B4: 1 | C4: Debt Equity | D4: =D5/D6 -> 3.9252586 | E4: =E5/E6 -> 3.492468 | F4: =F5/F6 -> 3.1993553 | G4: =E4 -> 3.492468 | H4: =D4 -> 3.9252586
C5: Total Financial Debt | D5: ='6. Output-BS'!E51+'6. Output-BS'!E52+'6. Output-BS'!E53+'6. Output-BS'!E54+'6. Output-BS'!E55+'6. Output-BS'!E74+'6. Output-BS'!E78+'6. Output-BS'!E79+'6. Output-BS'!E77 -> 3135167.8 | E5: ='6. Output-BS'!F51+'6. Output-BS'!F52+'6. Output-BS'!F53+'6. Output-BS'!F54+'6. Output-BS'!F55+'6. Output-BS'!F74+'6. Output-BS'!F78+'6. Output-BS'!F79+'6. Output-BS'!F77 -> 2518628 | F5: ='6. Output-BS'!G51+'6. Output-BS'!G52+'6. Output-BS'!G53+'6. Output-BS'!G54+'6. Output-BS'!G55+'6. Output-BS'!G74+'6. Output-BS'!G78+'6. Output-BS'!G79+'6. Output-BS'!G77 -> 2050224.1 | G5: =E5 -> 2518628 | H5: =D5 -> 3135167.8
C6: Total Tangible Net Worth | D6: ='6. Output-BS'!E97-'6. Output-BS'!E33-'6. Output-BS'!E34-'6. Output-BS'!E35-('6. Output-BS'!E93*0.25) -> 798716.24 | E6: ='6. Output-BS'!F97-'6. Output-BS'!F33-'6. Output-BS'!F34-'6. Output-BS'!F35-('6. Output-BS'!F93*0.25) -> 721159.94 | F6: ='6. Output-BS'!G97-'6. Output-BS'!G33-'6. Output-BS'!G34-'6. Output-BS'!G35-('6. Output-BS'!G93*0.25) -> 640824.14 | G6: =E6 -> 721159.94 | H6: =D6 -> 798716.24
B7: 2 | C7: Debt to Assets | D7: =D8/D9 -> 0.78528911 | E7: =E8/E9 -> 0.74091911 | F7: =F8/F9 -> 0.7093183 | G7: =E7 -> 0.74091911 | H7: =D7 -> 0.78528911
C8: Total Financial Debt | D8: =D5 -> 3135167.8 | E8: =E5 -> 2518628 | F8: =F5 -> 2050224.1 | G8: =E8 -> 2518628 | H8: =D8 -> 3135167.8
C9: Total Assets | D9: ='6. Output-BS'!E49 -> 3992374 | E9: ='6. Output-BS'!F49 -> 3399329.3 | F9: ='6. Output-BS'!G49 -> 2890414.8 | G9: =E9 -> 3399329.3 | H9: =D9 -> 3992374
B10: 3 | C10: Cash Ratio | D10: =D12/D14 -> 0.0061472341 | E10: =E12/E14 -> 0.014425013 | F10: =F12/F14 -> 0.00832317 | G10: =E10 -> 0.014425013 | H10: =D10 -> 0.0061472341
B11: 4 | C11: Current Ratio | D11: =D13/D14 -> 1.0405522 | E11: =E13/E14 -> 1.0276096 | F11: =F13/F14 -> 1.0849472 | G11: =E11 -> 1.0276096 | H11: =D11 -> 1.0405522
C12: Cash and easily marketable securities | D12: ='6. Output-BS'!E25+'6. Output-BS'!E23 -> 18841.322 | E12: ='6. Output-BS'!F25+'6. Output-BS'!F23 -> 36951.324 | F12: ='6. Output-BS'!G25+'6. Output-BS'!G23 -> 17409.703 | G12: =E12 -> 36951.324 | H12: =D12 -> 18841.322
C13: Current Assets | D13: ='6. Output-BS'!E27 -> 3189300.7 | E13: ='6. Output-BS'!F27 -> 2632339.6 | F13: ='6. Output-BS'!G27 -> 2269400.9 | G13: =E13 -> 2632339.6 | H13: =D13 -> 3189300.7
C14: Current Liabilites | D14: ='6. Output-BS'!E72 -> 3065008.1 | E14: ='6. Output-BS'!F72 -> 2561614.5 | F14: ='6. Output-BS'!G72 -> 2091715.4 | G14: =E14 -> 2561614.5 | H14: =D14 -> 3065008.1
B15: 5 | C15: Net Profit Margin | D15: =D16/D17 -> 0.054896988 | E15: =E16/E17 -> 0.04005365 | F15: =F16/F17 -> 0.080204317 | G15: =E15 -> 0.04005365 | H15: =D15 -> 0.054896988
C16: Net profit after tax | D16: ='7. Output IS'!E43 -> 77556.3 | E16: ='7. Output IS'!F43 -> 69535.797 | F16: ='7. Output IS'!G43 -> 111975.76 | G16: =E16 -> 69535.797 | H16: =D16 -> 77556.3
C17: Net Sales | D17: ='7. Output IS'!E13 -> 1412760.6 | E17: ='7. Output IS'!F13 -> 1736066.4 | F17: ='7. Output IS'!G13 -> 1396131.3 | G17: =E17 -> 1736066.4 | H17: =D17 -> 1412760.6
B18: 6 | C18: Return on Asset | D18: =D19/D20 -> 0.019426111 | E18: =E19/E20 -> 0.02045574 | F18: =F19/F20 -> 0.038740378 | G18: =E18 -> 0.02045574 | H18: =D18 -> 0.019426111
C19: Net profit after tax | D19: =D16 -> 77556.3 | E19: =E16 -> 69535.797 | F19: =F16 -> 111975.76 | G19: =E19 -> 69535.797 | H19: =D19 -> 77556.3
C20: Average Total Assets | D20: ='6. Output-BS'!E49 -> 3992374 | E20: ='6. Output-BS'!F49 -> 3399329.3 | F20: ='6. Output-BS'!G49 -> 2890414.8 | G20: =E20 -> 3399329.3 | H20: =D20 -> 3992374
B21: 7 | C21: Operating Profit to Operating Assets | D21: =D22/D23 -> 0.04652054 | E21: =E22/E23 -> 0.063539008 | F21: =F22/F23 -> 0.077093466 | G21: =E21 -> 0.063539008 | H21: =D21 -> 0.04652054
C22: Operating Profit | D22: ='7. Output IS'!E23 -> 171771.23 | E22: ='7. Output IS'!F23 -> 196928.31 | F22: ='7. Output IS'!G23 -> 199704.05 | G22: =E22 -> 196928.31 | H22: =D22 -> 171771.23
C23: Operating Assets | D23: ='6. Output-BS'!E49-'6. Output-BS'!E37-'6. Output-BS'!E38-'6. Output-BS'!E40-'6. Output-BS'!E36 -> 3692374 | E23: ='6. Output-BS'!F49-'6. Output-BS'!F37-'6. Output-BS'!F38-'6. Output-BS'!F40-'6. Output-BS'!F36 -> 3099329.3 | F23: ='6. Output-BS'!G49-'6. Output-BS'!G37-'6. Output-BS'!G38-'6. Output-BS'!G40-'6. Output-BS'!G36 -> 2590414.8 | G23: =E23 -> 3099329.3 | H23: =D23 -> 3692374
B24: 8 | C24: Interest Coverage | D24: =D25/D26 -> 2.1640484 | E24: =E25/E26 -> 1.6813178 | F24: =F25/F26 -> 2.9173829 | G24: =E24 -> 1.6813178 | H24: =D24 -> 2.1640484
C25: Earning Before Interest and Tax | D25: ='7. Output IS'!E36 -> 173746.24 | E25: ='7. Output IS'!F36 -> 199713.92 | F25: ='7. Output IS'!G36 -> 200442.43 | G25: =E25 -> 199713.92 | H25: =D25 -> 173746.24
C26: Interest Expense | D26: ='7. Output IS'!E37 -> 80287.596 | E26: ='7. Output IS'!F37 -> 118784.16 | F26: ='7. Output IS'!G37 -> 68706.248 | G26: =E26 -> 118784.16 | H26: =D26 -> 80287.596
B27: 9 | C27: DSCR | D27: =D28/D29 -> 1.4160266 | E27: =E28/E29 -> 1.2305544 | F27: =F28/F29 -> 1.713076 | G27: =E27 -> 1.2305544 | H27: =D27 -> 1.4160266
C28: Earning Before Interest Tax Depreciation Amortization | D28: ='7. Output IS'!E36+'7. Output IS'!E19 -> 194616.28 | E28: ='7. Output IS'!F36+'7. Output IS'!F19 -> 219104.24 | F28: ='7. Output IS'!G36+'7. Output IS'!G19 -> 213771.42 | G28: =E28 -> 219104.24 | H28: =D28 -> 194616.28
C29: Debts to be Serviced | D29: ='6. Output-BS'!E54+'6. Output-BS'!E55+'7. Output IS'!E37+'6. Output-BS'!E67 -> 137438.29 | E29: ='6. Output-BS'!F54+'6. Output-BS'!F55+'7. Output IS'!F37+'6. Output-BS'!F67 -> 178053.27 | F29: ='6. Output-BS'!G54+'6. Output-BS'!G55+'7. Output IS'!G37+'6. Output-BS'!G67 -> 124788.06 | G29: =E29 -> 178053.27 | H29: =D29 -> 137438.29
B30: 10 | C30: 3. Financial Debt to Operating Cash Flow (FDCF) | D30: =D31/D32 -> 29.810185 | E30: =E31/E32 -> 6.3218293 | F30: =F31/F32 -> -2.8349772 | G30: =E30 -> 6.3218293 | H30: =D30 -> 29.810185
C31: Total Financial Debt | D31: =D5 -> 3135167.8 | E31: =E5 -> 2518628 | F31: =F5 -> 2050224.1 | G31: =E31 -> 2518628 | H31: =D31 -> 3135167.8
C32: Operating Cash flow | D32: ='8. Output CF'!E11 -> 105171.03 | E32: ='8. Output CF'!F11 -> 398401.77 | F32: ='8. Output CF'!G11 -> -723188.92 | G32: =E32 -> 398401.77 | H32: =D32 -> 105171.03
B33: 11 | C33: Cashflow Coverage | D33: =D34/D35 -> 0.76522361 | E33: =E34/E35 -> 2.2375425 | F33: =F34/F35 -> -5.7953376 | G33: =E33 -> 2.2375425 | H33: =D33 -> 0.76522361
C34: Operating Cash flow | D34: ='8. Output CF'!E11 -> 105171.03 | E34: ='8. Output CF'!F11 -> 398401.77 | F34: ='8. Output CF'!G11 -> -723188.92 | G34: =E34 -> 398401.77 | H34: =D34 -> 105171.03
C35: Debt to be serviced | D35: =D29 -> 137438.29 | E35: =E29 -> 178053.27 | F35: =F29 -> 124788.06 | G35: =E35 -> 178053.27 | H35: =D35 -> 137438.29
B36: 12 | C36: 1. Stock Turnover Days (STD) | D36: =D37/D38*360 -> 0 | E36: =E37/E38*360 -> 0 | F36: =F37/F38*360 -> 0 | G36: =E36 -> 0 | H36: =D36 -> 0
C37: Total Inventory | D37: ='6. Output-BS'!E33 -> 0 | E37: ='6. Output-BS'!F33 -> 0 | F37: ='6. Output-BS'!G33 -> 0 | G37: =E37 -> 0 | H37: =D37 -> 0
C38: COGS | D38: ='7. Output IS'!E14 -> 1187045.5 | E38: ='7. Output IS'!F14 -> 1473623.9 | F38: ='7. Output IS'!G14 -> 1144305.5 | G38: =E38 -> 1473623.9 | H38: =D38 -> 1187045.5
B39: 13 | C39: 2. Trade Debtor Collection Days (TDCD) | D39: =(D40/D41)*360 -> 89.219452 | E39: =(E40/E41)*360 -> 195.71035 | F39: =(F40/F41)*360 -> 131.32814 | G39: =E39 -> 195.71035 | H39: =D39 -> 89.219452
C40: Total Accoutns Receivable | D40: ='6. Output-BS'!E13 -> 350127.01 | E40: ='6. Output-BS'!F13 -> 943794.93 | F40: ='6. Output-BS'!G13 -> 509309.24 | G40: =E40 -> 943794.93 | H40: =D40 -> 350127.01
C41: Sales | D41: ='7. Output IS'!E13 -> 1412760.6 | E41: ='7. Output IS'!F13 -> 1736066.4 | F41: ='7. Output IS'!G13 -> 1396131.3 | G41: =E41 -> 1736066.4 | H41: =D41 -> 1412760.6
...

Sheet Graph
B2: Components for Analysis
D3: ='6. Output-BS'!E9 -> 2025 | E3: ='6. Output-BS'!F9 -> 2024 | F3: ='6. Output-BS'!G9 -> 2023 | G3: =E3 -> 2024 | H3: =D3 -> 2025
B4: 1 | C4: Debt to Equity | D4: =D5/D6 -> 3.9984885 | E4: =E5/E6 -> 3.7136967 | F4: =F5/F6 -> 3.5104648 | G4: =E4 -> 3.7136967 | H4: =D4 -> 3.9984885
C5: Total Liabilites | D5: ='6. Output-BS'!E84 -> 3193657.7 | E5: ='6. Output-BS'!F84 -> 2678169.3 | F5: ='6. Output-BS'!G84 -> 2249590.6 | G5: =E5 -> 2678169.3 | H5: =D5 -> 3193657.7
C6: Total Tangible Net Worth | D6: ='6. Output-BS'!E97-'6. Output-BS'!E33-'6. Output-BS'!E34-'6. Output-BS'!E35-('6. Output-BS'!E93*0.25) -> 798716.24 | E6: ='6. Output-BS'!F97-'6. Output-BS'!F33-'6. Output-BS'!F34-'6. Output-BS'!F35-('6. Output-BS'!F93*0.25) -> 721159.94 | F6: ='6. Output-BS'!G97-'6. Output-BS'!G33-'6. Output-BS'!G34-'6. Output-BS'!G35-('6. Output-BS'!G93*0.25) -> 640824.14 | G6: =E6 -> 721159.94 | H6: =D6 -> 798716.24
B7: 2 | C7: Debt to Total Assets | D7: =D8/D9 -> 0.16107057 | E7: =E8/E9 -> 0.16162128 | F7: =F8/F9 -> 0.24636276 | G7: =E7 -> 0.16162128 | H7: =D7 -> 0.16107057
C8: Total Long Term Debt | D8: ='6. Output-BS'!E74+'6. Output-BS'!E78+'6. Output-BS'!E79 -> 128649.68 | E8: ='6. Output-BS'!F74+'6. Output-BS'!F78+'6. Output-BS'!F79 -> 116554.8 | F8: ='6. Output-BS'!G74+'6. Output-BS'!G78+'6. Output-BS'!G79 -> 157875.2 | G8: =E8 -> 116554.8 | H8: =D8 -> 128649.68
C9: Total Equity | D9: ='6. Output-BS'!E97 -> 798716.24 | E9: ='6. Output-BS'!F97 -> 721159.94 | F9: ='6. Output-BS'!G97 -> 640824.14 | G9: =E9 -> 721159.94 | H9: =D9 -> 798716.24
B10: 3 | C10: Cash Ratio | D10: =D12/D14 -> 0.0061472341 | E10: =E12/E14 -> 0.014425013 | F10: =F12/F14 -> 0.00832317 | G10: =E10 -> 0.014425013 | H10: =D10 -> 0.0061472341
B11: 4 | C11: Current Ratio | D11: =D13/D14 -> 1.0405522 | E11: =E13/E14 -> 1.0276096 | F11: =F13/F14 -> 1.0849472 | G11: =E11 -> 1.0276096 | H11: =D11 -> 1.0405522
C12: Cash and easily marketable securities | D12: ='6. Output-BS'!E25+'6. Output-BS'!E23 -> 18841.322 | E12: ='6. Output-BS'!F25+'6. Output-BS'!F23 -> 36951.324 | F12: ='6. Output-BS'!G25+'6. Output-BS'!G23 -> 17409.703 | G12: =E12 -> 36951.324 | H12: =D12 -> 18841.322
C13: Current Assets | D13: ='6. Output-BS'!E27 -> 3189300.7 | E13: ='6. Output-BS'!F27 -> 2632339.6 | F13: ='6. Output-BS'!G27 -> 2269400.9 | G13: =E13 -> 2632339.6 | H13: =D13 -> 3189300.7
C14: Current Liabilites | D14: ='6. Output-BS'!E72 -> 3065008.1 | E14: ='6. Output-BS'!F72 -> 2561614.5 | F14: ='6. Output-BS'!G72 -> 2091715.4 | G14: =E14 -> 2561614.5 | H14: =D14 -> 3065008.1
B15: 5 | C15: NPM | D15: =D16/D17 -> 0.054896988 | E15: =E16/E17 -> 0.04005365 | F15: =F16/F17 -> 0.080204317 | G15: =E15 -> 0.04005365 | H15: =D15 -> 0.054896988
C16: Net profit after tax | D16: ='7. Output IS'!E43 -> 77556.3 | E16: ='7. Output IS'!F43 -> 69535.797 | F16: ='7. Output IS'!G43 -> 111975.76 | G16: =E16 -> 69535.797 | H16: =D16 -> 77556.3
C17: Net Sales | D17: ='7. Output IS'!E13 -> 1412760.6 | E17: ='7. Output IS'!F13 -> 1736066.4 | F17: ='7. Output IS'!G13 -> 1396131.3 | G17: =E17 -> 1736066.4 | H17: =D17 -> 1412760.6
B18: 6 | C18: ROA | D18: =D19/D20 -> 0.019426111 | E18: =E19/E20 -> 0.02045574 | F18: =F19/F20 -> 0.038740378 | G18: =E18 -> 0.02045574 | H18: =D18 -> 0.019426111
C19: Net profit after tax | D19: =D16 -> 77556.3 | E19: =E16 -> 69535.797 | F19: =F16 -> 111975.76 | G19: =E19 -> 69535.797 | H19: =D19 -> 77556.3
C20: Average Total Assets | D20: ='6. Output-BS'!E49 -> 3992374 | E20: ='6. Output-BS'!F49 -> 3399329.3 | F20: ='6. Output-BS'!G49 -> 2890414.8 | G20: =E20 -> 3399329.3 | H20: =D20 -> 3992374
B21: 7 | C21: Operating Profit to Operating Assets | D21: =D22/D23 -> 0.043024835 | E21: =E22/E23 -> 0.057931519 | F21: =F22/F23 -> 0.069091832 | G21: =E21 -> 0.057931519 | H21: =D21 -> 0.043024835
C22: Operating Profit | D22: ='7. Output IS'!E23 -> 171771.23 | E22: ='7. Output IS'!F23 -> 196928.31 | F22: ='7. Output IS'!G23 -> 199704.05 | G22: =E22 -> 196928.31 | H22: =D22 -> 171771.23
C23: Average Total Assets | D23: ='6. Output-BS'!E49 -> 3992374 | E23: ='6. Output-BS'!F49 -> 3399329.3 | F23: ='6. Output-BS'!G49 -> 2890414.8 | G23: =E23 -> 3399329.3 | H23: =D23 -> 3992374
B24: 8 | C24: Int Cov | D24: =D25/D26 -> 2.1640484 | E24: =E25/E26 -> 1.6813178 | F24: =F25/F26 -> 2.9173829 | G24: =E24 -> 1.6813178 | H24: =D24 -> 2.1640484
C25: Earning Before Interest and Tax | D25: ='7. Output IS'!E36 -> 173746.24 | E25: ='7. Output IS'!F36 -> 199713.92 | F25: ='7. Output IS'!G36 -> 200442.43 | G25: =E25 -> 199713.92 | H25: =D25 -> 173746.24
C26: Interest Expense | D26: ='7. Output IS'!E37 -> 80287.596 | E26: ='7. Output IS'!F37 -> 118784.16 | F26: ='7. Output IS'!G37 -> 68706.248 | G26: =E26 -> 118784.16 | H26: =D26 -> 80287.596
B27: 9 | C27: DSCR | D27: =D28/D29 -> 1.4160266 | E27: =E28/E29 -> 1.2305544 | F27: =F28/F29 -> 1.713076 | G27: =E27 -> 1.2305544 | H27: =D27 -> 1.4160266
C28: Earning Before Interest Tax Depreciation Amortization | D28: ='7. Output IS'!E36+'7. Output IS'!E19 -> 194616.28 | E28: ='7. Output IS'!F36+'7. Output IS'!F19 -> 219104.24 | F28: ='7. Output IS'!G36+'7. Output IS'!G19 -> 213771.42 | G28: =E28 -> 219104.24 | H28: =D28 -> 194616.28
C29: Debts to be Serviced | D29: ='6. Output-BS'!E54+'6. Output-BS'!E55+'7. Output IS'!E37+'6. Output-BS'!E67 -> 137438.29 | E29: ='6. Output-BS'!F54+'6. Output-BS'!F55+'7. Output IS'!F37+'6. Output-BS'!F67 -> 178053.27 | F29: ='6. Output-BS'!G54+'6. Output-BS'!G55+'7. Output IS'!G37+'6. Output-BS'!G67 -> 124788.06 | G29: =E29 -> 178053.27 | H29: =D29 -> 137438.29
B30: 10 | C30: Financial Debt to Operating Cash Flow | D30: =D31/D32 -> 29.266778 | E30: =E31/E32 -> 6.1730621 | F30: =F31/F32 -> -2.7574293 | G30: =E30 -> 6.1730621 | H30: =D30 -> 29.266778
C31: Total Debt | D31: ='6. Output-BS'!E74+'6. Output-BS'!E77+'6. Output-BS'!E78+'6. Output-BS'!E79+'6. Output-BS'!E51+'6. Output-BS'!E52+'6. Output-BS'!E53+'6. Output-BS'!E55+'6. Output-BS'!E55 -> 3078017.1 | E31: ='6. Output-BS'!F74+'6. Output-BS'!F77+'6. Output-BS'!F78+'6. Output-BS'!F79+'6. Output-BS'!F51+'6. Output-BS'!F52+'6. Output-BS'!F53+'6. Output-BS'!F55+'6. Output-BS'!F55 -> 2459358.9 | F31: ='6. Output-BS'!G74+'6. Output-BS'!G77+'6. Output-BS'!G78+'6. Output-BS'!G79+'6. Output-BS'!G51+'6. Output-BS'!G52+'6. Output-BS'!G53+'6. Output-BS'!G55+'6. Output-BS'!G55 -> 1994142.3 | G31: =E31 -> 2459358.9 | H31: =D31 -> 3078017.1
C32: Operating Cash flow | D32: ='8. Output CF'!E11 -> 105171.03 | E32: ='8. Output CF'!F11 -> 398401.77 | F32: ='8. Output CF'!G11 -> -723188.92 | G32: =E32 -> 398401.77 | H32: =D32 -> 105171.03
B33: 11 | C33: Cash Cov | D33: =D34/D35 -> 0.76522361 | E33: =E34/E35 -> 2.2375425 | F33: =F34/F35 -> -5.7953376 | G33: =E33 -> 2.2375425 | H33: =D33 -> 0.76522361
C34: Operating Cash flow | D34: ='8. Output CF'!E11 -> 105171.03 | E34: ='8. Output CF'!F11 -> 398401.77 | F34: ='8. Output CF'!G11 -> -723188.92 | G34: =E34 -> 398401.77 | H34: =D34 -> 105171.03
C35: Debt to be serviced | D35: =D29 -> 137438.29 | E35: =E29 -> 178053.27 | F35: =F29 -> 124788.06 | G35: =E35 -> 178053.27 | H35: =D35 -> 137438.29
B36: 12 | C36: Stock Turnover Days | D36: =D37/D38*360 -> 0 | E36: =E37/E38*360 -> 0 | F36: =F37/F38*360 -> 0 | G36: =E36 -> 0 | H36: =D36 -> 0
C37: Total Inventory | D37: ='6. Output-BS'!E33 -> 0 | E37: ='6. Output-BS'!F33 -> 0 | F37: ='6. Output-BS'!G33 -> 0 | G37: =E37 -> 0 | H37: =D37 -> 0
C38: COGS | D38: ='7. Output IS'!E14 -> 1187045.5 | E38: ='7. Output IS'!F14 -> 1473623.9 | F38: ='7. Output IS'!G14 -> 1144305.5 | G38: =E38 -> 1473623.9 | H38: =D38 -> 1187045.5
B39: 13 | C39: Trade Debtor Collection Days | D39: =(D40/D41)*360 -> 89.219452 | E39: =(E40/E41)*360 -> 195.71035 | F39: =(F40/F41)*360 -> 131.32814 | G39: =E39 -> 195.71035 | H39: =D39 -> 89.219452
C40: Total Accoutns Receivable | D40: ='6. Output-BS'!E13 -> 350127.01 | E40: ='6. Output-BS'!F13 -> 943794.93 | F40: ='6. Output-BS'!G13 -> 509309.24 | G40: =E40 -> 943794.93 | H40: =D40 -> 350127.01
C41: Sales | D41: ='7. Output IS'!E13 -> 1412760.6 | E41: ='7. Output IS'!F13 -> 1736066.4 | F41: ='7. Output IS'!G13 -> 1396131.3 | G41: =E41 -> 1736066.4 | H41: =D41 -> 1412760.6
...

Sheet 9. Inputs-Analysis
B2: Components for Analysis
C3: Year | D3: ='6. Output-BS'!E9 -> 2025 | E3: ='6. Output-BS'!F9 -> 2024 | F3: ='6. Output-BS'!G9 -> 2023
B4: 1 | C4: 1. Financial Debt to Tangible Net Worth (DTN) | D4: =D5/D6 -> 3.9252586 | E4: =E5/E6 -> 3.492468 | F4: =F5/F6 -> 3.1993553
C5: Total Financial Debt | D5: ='6. Output-BS'!E51+'6. Output-BS'!E52+'6. Output-BS'!E53+'6. Output-BS'!E54+'6. Output-BS'!E55+'6. Output-BS'!E74+'6. Output-BS'!E78+'6. Output-BS'!E79+'6. Output-BS'!E77 -> 3135167.8 | E5: ='6. Output-BS'!F51+'6. Output-BS'!F52+'6. Output-BS'!F53+'6. Output-BS'!F54+'6. Output-BS'!F55+'6. Output-BS'!F74+'6. Output-BS'!F78+'6. Output-BS'!F79+'6. Output-BS'!F77 -> 2518628 | F5: ='6. Output-BS'!G51+'6. Output-BS'!G52+'6. Output-BS'!G53+'6. Output-BS'!G54+'6. Output-BS'!G55+'6. Output-BS'!G74+'6. Output-BS'!G78+'6. Output-BS'!G79+'6. Output-BS'!G77 -> 2050224.1 | G5: TCL+TNCL
C6: Total Tangible Net Worth | D6: ='6. Output-BS'!E97-'6. Output-BS'!E33-'6. Output-BS'!E34-'6. Output-BS'!E35 -> 798716.24 | E6: ='6. Output-BS'!F97-'6. Output-BS'!F33-'6. Output-BS'!F34-'6. Output-BS'!F35-('6. Output-BS'!F93*0.25) -> 721159.94 | F6: ='6. Output-BS'!G97-'6. Output-BS'!G33-'6. Output-BS'!G34-'6. Output-BS'!G35-('6. Output-BS'!G93*0.25) -> 640824.14 | G6: Equity-goodwil-patent-software-other intangibles-50% of revaluation reserve
B7: 2 | C7: 2. Financial Debt to Total Assets (DTA) | D7: =D8/D9 -> 0.78528911 | E7: =E8/E9 -> 0.74091911 | F7: =F8/F9 -> 0.7093183
C8: Total Financial Debt | D8: =D5 -> 3135167.8 | E8: =E5 -> 2518628 | F8: =F5 -> 2050224.1 | G8: Long term loan+ Long term Lease+ intercompany lease
C9: Total Assets | D9: ='6. Output-BS'!E49 -> 3992374 | E9: ='6. Output-BS'!F49 -> 3399329.3 | F9: ='6. Output-BS'!G49 -> 2890414.8
B10: 3 | C10: 2. Cash Ratio (Cash) | D10: =D12/D14 -> 0.0061472341 | E10: =E12/E14 -> 0.014425013 | F10: =F12/F14 -> 0.00832317
B11: 4 | C11: 1. Current Ratio (CR) | D11: =D13/D14 -> 1.0405522 | E11: =E13/E14 -> 1.0276096 | F11: =F13/F14 -> 1.0849472
C12: Cash and easily marketable securities | D12: ='6. Output-BS'!E25+'6. Output-BS'!E23 -> 18841.322 | E12: ='6. Output-BS'!F25+'6. Output-BS'!F23 -> 36951.324 | F12: ='6. Output-BS'!G25+'6. Output-BS'!G23 -> 17409.703 | G12: cash+bank balance+investment held for sale
C13: Current Assets | D13: ='6. Output-BS'!E27 -> 3189300.7 | E13: ='6. Output-BS'!F27 -> 2632339.6 | F13: ='6. Output-BS'!G27 -> 2269400.9 | G13: TCA
C14: Current Liabilites | D14: ='6. Output-BS'!E72 -> 3065008.1 | E14: ='6. Output-BS'!F72 -> 2561614.5 | F14: ='6. Output-BS'!G72 -> 2091715.4
B15: 5 | C15: 1. Net Profit Margin (NPM) | D15: =D16/D17 -> 0.054896988 | E15: =E16/E17 -> 0.04005365 | F15: =F16/F17 -> 0.080204317
C16: Net profit after tax | D16: ='7. Output IS'!E43 -> 77556.3 | E16: ='7. Output IS'!F43 -> 69535.797 | F16: ='7. Output IS'!G43 -> 111975.76
C17: Net Sales | D17: ='7. Output IS'!E13 -> 1412760.6 | E17: ='7. Output IS'!F13 -> 1736066.4 | F17: ='7. Output IS'!G13 -> 1396131.3
B18: 6 | C18: 2. Return on Assets (ROA) | D18: =D19/D20 -> 0.019426111 | E18: =E19/E20 -> 0.02045574 | F18: =F19/F20 -> 0.038740378
C19: Net profit after tax | D19: =D16 -> 77556.3 | E19: =E16 -> 69535.797 | F19: =F16 -> 111975.76
C20: Average Total Assets | D20: ='6. Output-BS'!E49 -> 3992374 | E20: ='6. Output-BS'!F49 -> 3399329.3 | F20: ='6. Output-BS'!G49 -> 2890414.8
B21: 7 | C21: 3. Operating Profit to Operating Assets (OPOA) | D21: =D22/D23 -> 0.04652054 | E21: =E22/E23 -> 0.063539008 | F21: =F22/F23 -> 0.077093466
C22: Operating Profit | D22: ='7. Output IS'!E23 -> 171771.23 | E22: ='7. Output IS'!F23 -> 196928.31 | F22: ='7. Output IS'!G23 -> 199704.05
C23: Operating Assets | D23: ='6. Output-BS'!E49-'6. Output-BS'!E37-'6. Output-BS'!E38-'6. Output-BS'!E40-'6. Output-BS'!E36 -> 3692374 | E23: ='6. Output-BS'!F49-'6. Output-BS'!F37-'6. Output-BS'!F38-'6. Output-BS'!F40-'6. Output-BS'!F36 -> 3099329.3 | F23: ='6. Output-BS'!G49-'6. Output-BS'!G37-'6. Output-BS'!G38-'6. Output-BS'!G40-'6. Output-BS'!G36 -> 2590414.8
B24: 8 | C24: 1. Interest Coverage (IC) | D24: =D25/D26 -> 2.1640484 | E24: =E25/E26 -> 1.6813178 | F24: =F25/F26 -> 2.9173829
C25: Earning Before Interest and Tax | D25: ='7. Output IS'!E36 -> 173746.24 | E25: ='7. Output IS'!F36 -> 199713.92 | F25: ='7. Output IS'!G36 -> 200442.43
C26: Interest Expense | D26: ='7. Output IS'!E37 -> 80287.596 | E26: ='7. Output IS'!F37 -> 118784.16 | F26: ='7. Output IS'!G37 -> 68706.248
B27: 9 | C27: 2. Debt Service Coverage Ratio (DSCR) | D27: =D28/D29 -> 1.4160266 | E27: =E28/E29 -> 1.2305544 | F27: =F28/F29 -> 1.713076
C28: Earning Before Interest Tax Depreciation Amortization | D28: ='7. Output IS'!E36+'7. Output IS'!E19 -> 194616.28 | E28: ='7. Output IS'!F36+'7. Output IS'!F19 -> 219104.24 | F28: ='7. Output IS'!G36+'7. Output IS'!G19 -> 213771.42
C29: Debts to be Serviced | D29: ='6. Output-BS'!E54+'6. Output-BS'!E55+'7. Output IS'!E37+'6. Output-BS'!E67 -> 137438.29 | E29: ='6. Output-BS'!F54+'6. Output-BS'!F55+'7. Output IS'!F37+'6. Output-BS'!F67 -> 178053.27 | F29: ='6. Output-BS'!G54+'6. Output-BS'!G55+'7. Output IS'!G37+'6. Output-BS'!G67 -> 124788.06
B30: 10 | C30: 3. Operating Cashflow to Debt Ratio (CDR) | D30: =D32/D31 -> 0.033545581 | E30: =E32/E31 -> 0.15818206 | F30: =F32/F31 -> -0.35273652
C31: Total Financial Debt | D31: =D5 -> 3135167.8 | E31: =E5 -> 2518628 | F31: =F5 -> 2050224.1
C32: Operating Cash flow | D32: ='8. Output CF'!E11 -> 105171.03 | E32: ='8. Output CF'!F11 -> 398401.77 | F32: ='8. Output CF'!G11 -> -723188.92
B33: 11 | C33: 4. Cashflow Coverage Ratio (CCR) | D33: =D34/D35 -> 0.76522361 | E33: =E34/E35 -> 2.2375425 | F33: =F34/F35 -> -5.7953376
C34: Operating Cash flow | D34: ='8. Output CF'!E11 -> 105171.03 | E34: ='8. Output CF'!F11 -> 398401.77 | F34: ='8. Output CF'!G11 -> -723188.92
C35: Debt to be serviced | D35: =D29 -> 137438.29 | E35: =E29 -> 178053.27 | F35: =F29 -> 124788.06
B36: 12 | C36: 1. Stock Turnover Days (STD) | D36: =D37/D38*360 -> 823.7278 | E36: =E37/E38*360 -> 377.98396 | F36: =F37/F38*360 -> 502.13632
C37: Total Inventory | D37: ='6. Output-BS'!E12 -> 2716117.7 | E37: ='6. Output-BS'!F12 -> 1547239.4 | F37: ='6. Output-BS'!G12 -> 1596103.7
C38: COGS | D38: ='7. Output IS'!E14 -> 1187045.5 | E38: ='7. Output IS'!F14 -> 1473623.9 | F38: ='7. Output IS'!G14 -> 1144305.5
B39: 13 | C39: 2. Trade Debtor Collection Days (TDCD) | D39: =(D40/D41)*360 -> 89.219452 | E39: =(E40/E41)*360 -> 195.71035 | F39: =(F40/F41)*360 -> 131.32814
C40: Total Accoutns Receivable | D40: ='6. Output-BS'!E13 -> 350127.01 | E40: ='6. Output-BS'!F13 -> 943794.93 | F40: ='6. Output-BS'!G13 -> 509309.24
C41: Sales | D41: ='7. Output IS'!E13 -> 1412760.6 | E41: ='7. Output IS'!F13 -> 1736066.4 | F41: ='7. Output IS'!G13 -> 1396131.3
...

Sheet 9. Quantitative Analysis
A1: Internal Credit Risk Score Sheet
A2: Quantitative Analysis
A3: File / Reference No: | B3: ='11. Detail Managment Report'!D2 -> Outpace Spinning Mills Ltd
A4: Borrowe Name | B4: ='11. Detail Managment Report'!D3 -> Outpace Spinning Mills Ltd
A5: Group Name (if any) | B5: ='11. Detail Managment Report'!D4 -> Outright Group
A6: Industry Name | B6: ='11. Detail Managment Report'!D5 -> 2. Textile | S6: Score | T6: =C55 -> 0.36666667 | U6: =1-T6 -> 0.63333333
A7: Latest CIB Status | B7: ='11. Detail Managment Report'!D6 -> Standard
A8: Audit Status | B8: ='11. Detail Managment Report'!D7 -> Unaudited
A9: Auditor Name | B9: ='11. Detail Managment Report'!D8 -> Dewan Nazrul Islam & Co.
A10: Analyst Name, Designations | B10: ='11. Detail Managment Report'!D9 -> Md. Matiur Rahman, SRM
A11: Verifier Name, Designation | B11: ='11. Detail Managment Report'!D10 -> Farhana Afrin, SM
A13: Date of Analysis | B13: ='11. Detail Managment Report'!D12 -> 45652
A14: Date of Financials | B14: ='11. Detail Managment Report'!D13 -> 45473
A16: Quantitative Indicators (60)
A17: Criteria | B17: Parameter | C17: Scale | D17: Actual Parameter | E17: Score Obtained
A18: A. Leverage | C18: 10 | E18: =E19+E21 -> 1
A19: ='11. Detail Managment Report'!C18 -> 1. Financial Debt to Tangible Net Worth (DTN) | C19: 7 | D19: ='9. Inputs-Analysis'!D4 -> 3.9252586 | E19: ='11. Detail Managment Report'!E18 -> 0
A21: ='11. Detail Managment Report'!C19 -> 2. Financial Debt to Total Assets (DTA) | C21: 3 | D21: ='9. Inputs-Analysis'!D7 -> 0.78528911 | E21: ='11. Detail Managment Report'!E19 -> 1
A23: B. Liquidity | C23: 10 | E23: =E24+E26 -> 5
A24: ='11. Detail Managment Report'!C21 -> 1. Current Ratio (CR) | C24: 7 | D24: ='9. Inputs-Analysis'!D11 -> 1.0405522 | E24: ='11. Detail Managment Report'!E21 -> 5
A26: ='11. Detail Managment Report'!C22 -> 2. Cash Ratio (Cash) | C26: 3 | D26: ='9. Inputs-Analysis'!D10 -> 0.0061472341 | E26: ='11. Detail Managment Report'!E22 -> 0
A28: C. Profitability | C28: 10 | E28: =E29+E31+E33 -> 5
A29: ='11. Detail Managment Report'!C24 -> 1. Net Profit Margin (NPM) | C29: 5 | D29: ='9. Inputs-Analysis'!D15 -> 0.054896988 | E29: ='11. Detail Managment Report'!E24 -> 3
A31: ='11. Detail Managment Report'!C25 -> 2. Return on Assets (ROA) | C31: 3 | D31: ='9. Inputs-Analysis'!D18 -> 0.019426111 | E31: ='11. Detail Managment Report'!E25 -> 1
A33: ='11. Detail Managment Report'!C26 -> 3. Operating Profit to Operating Assets (OPOA) | C33: 2 | D33: ='9. Inputs-Analysis'!D21 -> 0.04652054 | E33: ='11. Detail Managment Report'!E26 -> 1
A35: D. Coverage | C35: 15 | E35: =E36+E38+E40+E42 -> 6
A36: ='11. Detail Managment Report'!C28 -> 1. Interest Coverage (IC) | C36: 3 | D36: ='9. Inputs-Analysis'!D24 -> 2.1640484 | E36: ='11. Detail Managment Report'!E28 -> 1
A38: ='11. Detail Managment Report'!C29 -> 2. Debt Service Coverage Ratio (DSCR) | C38: 5 | D38: ='9. Inputs-Analysis'!D27 -> 1.4160266 | E38: ='11. Detail Managment Report'!E29 -> 2
A40: ='11. Detail Managment Report'!C30 -> 3. Operating Cashflow to Debt Ratio (CDR) | C40: 4 | D40: ='9. Inputs-Analysis'!D30 -> 0.033545581 | E40: ='11. Detail Managment Report'!E30 -> 1
A42: ='11. Detail Managment Report'!C31 -> 4. Cashflow Coverage Ratio (CCR) | C42: 3 | D42: ='9. Inputs-Analysis'!D33 -> 0.76522361 | E42: ='11. Detail Managment Report'!E31 -> 2
A44: E. Operational Efficiency | C44: 10 | E44: =E45+E47+E49 -> 3
A45: ='11. Detail Managment Report'!C33 -> 1. Stock Turnover Days (STD) | D45: ='9. Inputs-Analysis'!D36 -> 823.7278 | E45: ='11. Detail Managment Report'!E33 -> 0
A47: ='11. Detail Managment Report'!C34 -> 2. Trade Debtor Collection Days (TDCD) | D47: ='9. Inputs-Analysis'!D39 -> 89.219452 | E47: ='11. Detail Managment Report'!E34 -> 2
A49: ='11. Detail Managment Report'!C35 -> 3. Asset Turnover (AT) | D49: ='9. Inputs-Analysis'!D42 -> 0.35386479 | E49: ='11. Detail Managment Report'!E35 -> 1
A50: F. Earning Quality | C50: 5 | E50: =E51+E53 -> 2
A51: ='11. Detail Managment Report'!C37 -> 1. Operating Cash Flow to Sales (CFS) | C51: 3 | D51: ='9. Inputs-Analysis'!D45 -> 0.074443631 | E51: ='11. Detail Managment Report'!E37 -> 2
A53: ='11. Detail Managment Report'!C38 -> 2. Cashflow based accrual ratio (CAR) | C53: 2 | D53: ='9. Inputs-Analysis'!D48 -> 0.0077292885 | E53: ='11. Detail Managment Report'!E38 -> 0
A54: Total | C54: =C50+C44+C35+C28+C23+C18 -> 60 | E54: =E50+E44+E35+E28+E23+E18 -> 22
A55: Percentage | C55: =E54/C54 -> 0.36666667

Sheet 10. Qualitative Analysis
B1: Qualitative Analysis
B2: ='11. Detail Managment Report'!B2:C2 -> File / Reference No: | D2: ='11. Detail Managment Report'!D2 -> Outpace Spinning Mills Ltd
B3: ='11. Detail Managment Report'!B3:C3 -> Borrower Name | D3: ='11. Detail Managment Report'!D3 -> Outpace Spinning Mills Ltd
